Workbook

Sheet Catalogue
A1: Photo | B1: Product ID | C1: Supplier Code | D1: Product Name | E1: Brand | F1: Master Category | G1: Sub Category / Design | H1: Material | I1: Unit Type | J1: Bundle (m) | K1: Buying Price (₹) | L1: Selling Price (₹) | M1: MRP (₹) | N1: Margin % | O1: GST Rate | P1: HSN Code | Q1: Stock Qty | R1: Reorder Lvl | S1: Stock Status | T1: Stock per Log | U1: Log Match | V1: First Received | W1: Supplier | X1: Image URL | Y1: Photo Quality | Z1: Live on Site | AA1: Listing Status | AB1: Sticker | AC1: Description | AD1: Notes
B2: NE1386 | C2: NE1386 | D2: Midnight Beaded Neckline Appliqué | E2: TRESOR | F2: Laces | G2: Patch | H2: Mixed | I2: bundle | K2: 700 | L2: 1200 | M2: 1200 | N2: =IF(OR(K2="",L2=""),"",(L2-K2)/L2) | O2: 0.05 | Q2: 1 | R2: 1 | S2: =IF(Q2="","",IF(Q2<=0,"OUT OF STOCK",IF(Q2<=R2,"REORDER","OK"))) | T2: =IF(B2="","",SUMIFS('Stock Log'!$D$2:$D$600,'Stock Log'!$B$2:$B$600,B2)) | U2: =IF(B2="","",IF(T2=Q2,"OK","CHECK")) | V2: 2026-07-09 | W2: Supplier A (rename me) | X2: https://tresorcouture.in/products/lace/NE1386.jpg | Y2: Studio | Z2: Yes | AA2: Active | AC2: A curved neckline appliqué worked entirely in black — beaded florals, sequin petals and corded scrolls on fine net, edged with picot beading. Stitch it to a blouse or gown neckline for instant couture depth. Sold per piece.
B3: NE1386-S31 | C3: NE1386-S31 | D3: Orchid & Sage Beaded Neckline Appliqué | E3: TRESOR | F3: Laces | G3: Patch | H3: Mixed | I3: bundle | K3: 700 | L3: 1200 | M3: 1200 | N3: =IF(OR(K3="",L3=""),"",(L3-K3)/L3) | O3: 0.05 | Q3: 1 | R3: 1 | S3: =IF(Q3="","",IF(Q3<=0,"OUT OF STOCK",IF(Q3<=R3,"REORDER","OK"))) | T3: =IF(B3="","",SUMIFS('Stock Log'!$D$2:$D$600,'Stock Log'!$B$2:$B$600,B3)) | U3: =IF(B3="","",IF(T3=Q3,"OK","CHECK")) | V3: 2026-07-09 | W3: Supplier A (rename me) | X3: https://tresorcouture.in/products/lace/NE1386-S31.jpg | Y3: Studio | Z3: Yes | AA3: Active | AC3: A V-neckline appliqué in orchid pink and sage: velvet petals, pearl flower hearts, silver bead scrolls and sequin blossoms on grey net, with pearl drops along the outline. Sold per piece.
B4: NE1386-S32 | C4: NE1386-S32 | D4: Plum Vine Beaded Neckline Appliqué | E4: TRESOR | F4: Laces | G4: Patch | H4: Mixed | I4: bundle | K4: 700 | L4: 1200 | M4: 1200 | N4: =IF(OR(K4="",L4=""),"",(L4-K4)/L4) | O4: 0.05 | Q4: 1 | R4: 1 | S4: =IF(Q4="","",IF(Q4<=0,"OUT OF STOCK",IF(Q4<=R4,"REORDER","OK"))) | T4: =IF(B4="","",SUMIFS('Stock Log'!$D$2:$D$600,'Stock Log'!$B$2:$B$600,B4)) | U4: =IF(B4="","",IF(T4=Q4,"OK","CHECK")) | V4: 2026-07-09 | W4: Supplier A (rename me) | X4: https://tresorcouture.in/products/lace/NE1386-S32.jpg | Y4: Studio | Z4: Yes | AA4: Active | AC4: Plum and mauve ribbon-work blossoms wind through silver-beaded scrolls and sage leaves on black net, edged in pearl picots — a deeper, moodier take on the beaded neckline. Sold per piece.
B5: NE1386-S33 | C5: NE1386-S33 | D5: Pastel Confetti Beaded Neckline Appliqué | E5: TRESOR | F5: Laces | G5: Patch | H5: Mixed | I5: bundle | K5: 700 | L5: 1200 | M5: 1200 | N5: =IF(OR(K5="",L5=""),"",(L5-K5)/L5) | O5: 0.05 | Q5: 1 | R5: 1 | S5: =IF(Q5="","",IF(Q5<=0,"OUT OF STOCK",IF(Q5<=R5,"REORDER","OK"))) | T5: =IF(B5="","",SUMIFS('Stock Log'!$D$2:$D$600,'Stock Log'!$B$2:$B$600,B5)) | U5: =IF(B5="","",IF(T5=Q5,"OK","CHECK")) | V5: 2026-07-09 | W5: Supplier A (rename me) | X5: https://tresorcouture.in/products/lace/NE1386-S33.jpg | Y5: Studio | Z5: Yes | AA5: Active | AC5: The neckline appliqué in sugared pastels — baby pink, powder blue, butter yellow and mint petals with pearl centres and silver bead scrolls, scalloped in white. Made for daytime mehendi and haldi palettes. Sold per piece.
B6: NE1386-S34 | C6: NE1386-S34 | D6: Ivory Bridal Beaded Neckline Appliqué | E6: TRESOR | F6: Laces | G6: Patch | H6: Mixed | I6: bundle | K6: 700 | L6: 1200 | M6: 1200 | N6: =IF(OR(K6="",L6=""),"",(L6-K6)/L6) | O6: 0.05 | Q6: 1 | R6: 1 | S6: =IF(Q6="","",IF(Q6<=0,"OUT OF STOCK",IF(Q6<=R6,"REORDER","OK"))) | T6: =IF(B6="","",SUMIFS('Stock Log'!$D$2:$D$600,'Stock Log'!$B$2:$B$600,B6)) | U6: =IF(B6="","",IF(T6=Q6,"OK","CHECK")) | V6: 2026-07-09 | W6: Supplier A (rename me) | X6: https://tresorcouture.in/products/lace/NE1386-S34.jpg | Y6: Studio | Z6: Yes | AA6: Active | AC6: All-ivory florals, pearl sprays and crystal scrolls on sheer net — the bridal colourway of the beaded neckline, ready for a white or champagne gown. Sold per piece.
B7: NE1386-S35 | C7: NE1386-S35 | D7: Gilded Mirror V-Neckline Appliqué | E7: TRESOR | F7: Laces | G7: Patch | H7: Mixed | I7: bundle | K7: 700 | L7: 1200 | M7: 1200 | N7: =IF(OR(K7="",L7=""),"",(L7-K7)/L7) | O7: 0.05 | Q7: 1 | R7: 1 | S7: =IF(Q7="","",IF(Q7<=0,"OUT OF STOCK",IF(Q7<=R7,"REORDER","OK"))) | T7: =IF(B7="","",SUMIFS('Stock Log'!$D$2:$D$600,'Stock Log'!$B$2:$B$600,B7)) | U7: =IF(B7="","",IF(T7=Q7,"OK","CHECK")) | V7: 2026-07-09 | W7: Supplier A (rename me) | X7: https://tresorcouture.in/products/lace/NE1386-S35.jpg | Y7: Studio | Z7: Yes | AA7: Active | AC7: A deep-V neckline panel in solid gold work: pearl-edged zari braid arms meeting a mirror-and-bead lattice bib, finished with picot pearls all round. Heavy, regal, festive. Sold per piece.
B8: NO-CODE-S23 | C8: NO-CODE-S23 | D8: Antique Gold Jaal Scallop Border | E8: TRESOR | F8: Laces | G8: Patch | H8: Mixed | I8: unit | K8: 280 | L8: 480 | M8: 480 | N8: =IF(OR(K8="",L8=""),"",(L8-K8)/L8) | O8: 0.05 | Q8: 1 | R8: 1 | S8: =IF(Q8="","",IF(Q8<=0,"OUT OF STOCK",IF(Q8<=R8,"REORDER","OK"))) | T8: =IF(B8="","",SUMIFS('Stock Log'!$D$2:$D$600,'Stock Log'!$B$2:$B$600,B8)) | U8: =IF(B8="","",IF(T8=Q8,"OK","CHECK")) | V8: 2026-07-09 | W8: Supplier A (rename me) | X8: https://tresorcouture.in/products/lace/NO-CODE-S23.jpg | Y8: Studio | Z8: Yes | AA8: Active | AC8: Scalloped fans of antique-gold zari and bugle beads, each medallion set with pearls, linked by woven leaf motifs — a temple-jaal border by the piece for blouse hems and sleeve edges.
B9: 6343 | C9: 6343 | D9: Ivory Pearl Bouquet Bridal Border | E9: TRESOR | F9: Laces | G9: Trim & Edging | H9: Mixed | I9: bundle | J9: 9 | K9: 4060 | L9: 7000 | M9: 7000 | N9: =IF(OR(K9="",L9=""),"",(L9-K9)/L9) | O9: 0.05 | Q9: 0 | R9: 1 | S9: =IF(Q9="","",IF(Q9<=0,"OUT OF STOCK",IF(Q9<=R9,"REORDER","OK"))) | T9: =IF(B9="","",SUMIFS('Stock Log'!$D$2:$D$600,'Stock Log'!$B$2:$B$600,B9)) | U9: =IF(B9="","",IF(T9=Q9,"OK","CHECK")) | V9: 2026-07-09 | W9: Supplier A (rename me) | X9: https://tresorcouture.in/products/lace/6343.jpg | Y9: Studio | Z9: Yes | AA9: Active | AC9: A wide ivory net border worked with velvet floral bouquets, seed pearls, silver zari leaves and sequin sprays, finishing in a softly scalloped edge with a sequin-run header. A full 9-metre reel — enough for a lehenga hem or a dupatta on all sides.
B10: 6988 | C10: 6988 | D10: Magenta Gota Braid with Pearl Rows | E10: TRESOR | F10: Laces | G10: Trim & Edging | H10: Mixed | I10: bundle | J10: 9 | K10: 580 | L10: 999 | M10: 999 | N10: =IF(OR(K10="",L10=""),"",(L10-K10)/L10) | O10: 0.05 | Q10: 0 | R10: 1 | S10: =IF(Q10="","",IF(Q10<=0,"OUT OF STOCK",IF(Q10<=R10,"REORDER","OK"))) | T10: =IF(B10="","",SUMIFS('Stock Log'!$D$2:$D$600,'Stock Log'!$B$2:$B$600,B10)) | U10: =IF(B10="","",IF(T10=Q10,"OK","CHECK")) | V10: 2026-07-09 | W10: Supplier A (rename me) | X10: https://tresorcouture.in/products/lace/6988.jpg | Y10: Studio | Z10: Yes | AA10: Active | AC10: A narrow magenta satin band carrying antique-gold wire scrollwork, a run of half-pearls and a fine gold chain along the footing. A classic gota-style braid for sleeve cuffs, necklines and dupatta edges. 9-metre reel.
B11: HA3858 | C11: HA3858 | D11: Champagne Sequin Encrusted Band | E11: TRESOR | F11: Laces | G11: Trim & Edging | H11: Mixed | I11: bundle | J11: 9 | K11: 750 | L11: 1299 | M11: 1299 | N11: =IF(OR(K11="",L11=""),"",(L11-K11)/L11) | O11: 0.05 | Q11: 1 | R11: 1 | S11: =IF(Q11="","",IF(Q11<=0,"OUT OF STOCK",IF(Q11<=R11,"REORDER","OK"))) | T11: =IF(B11="","",SUMIFS('Stock Log'!$D$2:$D$600,'Stock Log'!$B$2:$B$600,B11)) | U11: =IF(B11="","",IF(T11=Q11,"OK","CHECK")) | V11: 2026-07-09 | W11: Supplier A (rename me) | X11: https://tresorcouture.in/products/lace/HA3858.jpg | Y11: Studio | Z11: Yes | AA11: Active | AC11: Densely packed champagne-gold sequins on a nude net base — the whole band reads as one strip of shimmer. Cut it for blouse borders, waistbands or a lehenga hem that catches every light. 9-metre reel.
B12: HA4536 | C12: HA4536 | D12: Pastel Deco Beadwork Border | E12: TRESOR | F12: Laces | G12: Trim & Edging | H12: Mixed | I12: bundle | J12: 3 | K12: 2200 | L12: 3800 | M12: 3800 | N12: =IF(OR(K12="",L12=""),"",(L12-K12)/L12) | O12: 0.05 | Q12: 0 | R12: 1 | S12: =IF(Q12="","",IF(Q12<=0,"OUT OF STOCK",IF(Q12<=R12,"REORDER","OK"))) | T12: =IF(B12="","",SUMIFS('Stock Log'!$D$2:$D$600,'Stock Log'!$B$2:$B$600,B12)) | U12: =IF(B12="","",IF(T12=Q12,"OK","CHECK")) | V12: 2026-07-09 | W12: Supplier A (rename me) | X12: https://tresorcouture.in/products/lace/HA4536.jpg | Y12: Studio | Z12: Yes | AA12: Active | AC12: A wide statement border of overlapping deco arches: turquoise, lilac, peach and taupe bugle beads laid in fans, edged with pearl strings, rhinestone chain and butter-yellow threadwork on beige net. Sold as a 3-metre length — one showpiece border.
B13: HA6293 | C13: HA6293 | D13: Ivory Guipure Daisy Lace with Pearls | E13: TRESOR | F13: Laces | G13: Trim & Edging | H13: Mixed | I13: bundle | J13: 8 | K13: 2780 | L13: 4800 | M13: 4800 | N13: =IF(OR(K13="",L13=""),"",(L13-K13)/L13) | O13: 0.05 | Q13: 1 | R13: 1 | S13: =IF(Q13="","",IF(Q13<=0,"OUT OF STOCK",IF(Q13<=R13,"REORDER","OK"))) | T13: =IF(B13="","",SUMIFS('Stock Log'!$D$2:$D$600,'Stock Log'!$B$2:$B$600,B13)) | U13: =IF(B13="","",IF(T13=Q13,"OK","CHECK")) | V13: 2026-07-09 | W13: Supplier A (rename me) | X13: https://tresorcouture.in/products/lace/HA6293.jpg | Y13: Studio | Z13: Yes | AA13: Active | AC13: Free-standing guipure star-flowers in ivory, each centred with a pearl cluster and dressed with crystal beads and sequins, linked petal-to-petal with bead drops along both edges. 8-metre reel of true cutwork lace — no net backing to trim away.
B14: HA6320 | C14: HA6320 | D14: Berry Garden Dimensional Floral Trim | E14: TRESOR | F14: Laces | G14: Trim & Edging | H14: Mixed | I14: bundle | J14: 3 | K14: 2780 | L14: 4800 | M14: 4800 | N14: =IF(OR(K14="",L14=""),"",(L14-K14)/L14) | O14: 0.05 | Q14: 0 | R14: 1 | S14: =IF(Q14="","",IF(Q14<=0,"OUT OF STOCK",IF(Q14<=R14,"REORDER","OK"))) | T14: =IF(B14="","",SUMIFS('Stock Log'!$D$2:$D$600,'Stock Log'!$B$2:$B$600,B14)) | U14: =IF(B14="","",IF(T14=Q14,"OK","CHECK")) | V14: 2026-07-09 | W14: Supplier A (rename me) | X14: https://tresorcouture.in/products/lace/HA6320.jpg | Y14: Studio | Z14: Yes | AA14: Active | AC14: A joyful, dimensional trim: white organza blossoms rise off grey net between beaded berries in orange, cobalt, raspberry and lime, with fern leaves in green thread and a trailing pearl vine. Sold as a 3-metre length for necklines and hem features.
B15: HA6378 | C15: HA6378 | D15: Soft Chantilly Scallop Lace · White | E15: TRESOR | F15: Laces | G15: Trim & Edging | H15: Mixed | I15: bundle | J15: 10 | K15: 2900 | L15: 4999 | M15: 4999 | N15: =IF(OR(K15="",L15=""),"",(L15-K15)/L15) | O15: 0.05 | Q15: 1 | R15: 1 | S15: =IF(Q15="","",IF(Q15<=0,"OUT OF STOCK",IF(Q15<=R15,"REORDER","OK"))) | T15: =IF(B15="","",SUMIFS('Stock Log'!$D$2:$D$600,'Stock Log'!$B$2:$B$600,B15)) | U15: =IF(B15="","",IF(T15=Q15,"OK","CHECK")) | V15: 2026-07-09 | W15: Supplier A (rename me) | X15: https://tresorcouture.in/products/lace/HA6378.jpg | Y15: Needs reshoot | Z15: Yes | AA15: Active | AC15: Soft white corded lace with rounded scallop repeats and a fine floral fill, supplied as generous scalloped panels. A 10-metre reel for overlays, veils and sleeve work. | AD15: Reshoot flagged — warehouse snapshot
B16: HA6387 | C16: HA6387 | D16: Blush Iridescent Floral Net Border | E16: TRESOR | F16: Laces | G16: Trim & Edging | H16: Mixed | I16: bundle | J16: 10 | K16: 2780 | L16: 4800 | M16: 4800 | N16: =IF(OR(K16="",L16=""),"",(L16-K16)/L16) | O16: 0.05 | Q16: 1 | R16: 1 | S16: =IF(Q16="","",IF(Q16<=0,"OUT OF STOCK",IF(Q16<=R16,"REORDER","OK"))) | T16: =IF(B16="","",SUMIFS('Stock Log'!$D$2:$D$600,'Stock Log'!$B$2:$B$600,B16)) | U16: =IF(B16="","",IF(T16=Q16,"OK","CHECK")) | V16: 2026-07-09 | W16: Supplier A (rename me) | X16: https://tresorcouture.in/products/lace/HA6387.jpg | Y16: Studio | Z16: Yes | AA16: Active | AC16: Tone-on-tone blush flowers outlined in dusty-rose thread, their petals filled with iridescent sequins and pastel bugle-bead rays that shift pink, mint and lilac as the light moves. On blush net, 10-metre reel.
B17: HA6674 | C17: HA6674 | D17: Mint Fan Scallop Beaded Trim | E17: TRESOR | F17: Laces | G17: Trim & Edging | H17: Mixed | I17: bundle | J17: 9.5 | K17: 1680 | L17: 2899 | M17: 2899 | N17: =IF(OR(K17="",L17=""),"",(L17-K17)/L17) | O17: 0.05 | Q17: 1 | R17: 1 | S17: =IF(Q17="","",IF(Q17<=0,"OUT OF STOCK",IF(Q17<=R17,"REORDER","OK"))) | T17: =IF(B17="","",SUMIFS('Stock Log'!$D$2:$D$600,'Stock Log'!$B$2:$B$600,B17)) | U17: =IF(B17="","",IF(T17=Q17,"OK","CHECK")) | V17: 2026-07-09 | W17: Supplier A (rename me) | X17: https://tresorcouture.in/products/lace/HA6674.jpg | Y17: Studio | Z17: Yes | AA17: Active | AC17: Arched fans of silver bugle beads and sequins on mint net, each scallop dressed with mint pearls and finished with crystal and pearl drops along the edge. Cool, icy and light. 9.5-metre reel.
B18: HA6758 | C18: HA6758 | D18: Royal Purple Zari Sari Border | E18: TRESOR | F18: Laces | G18: Trim & Edging | H18: Mixed | I18: bundle | J18: 9 | K18: 2440 | L18: 4200 | M18: 4200 | N18: =IF(OR(K18="",L18=""),"",(L18-K18)/L18) | O18: 0.05 | Q18: 1 | R18: 1 | S18: =IF(Q18="","",IF(Q18<=0,"OUT OF STOCK",IF(Q18<=R18,"REORDER","OK"))) | T18: =IF(B18="","",SUMIFS('Stock Log'!$D$2:$D$600,'Stock Log'!$B$2:$B$600,B18)) | U18: =IF(B18="","",IF(T18=Q18,"OK","CHECK")) | V18: 2026-07-09 | W18: Supplier A (rename me) | X18: https://tresorcouture.in/products/lace/HA6758.jpg | Y18: Studio | Z18: Yes | AA18: Active | AC18: A wide royal-purple satin border carrying dense antique-gold zari: a scalloped fan edge, beadwork medallions, sequin runs and a corded centre line. Made for sari falls and lehenga hems that want traditional weight. 9-metre reel.
B19: HA6767 | C19: HA6767 | D19: Navy & Gold Picot Ribbon | E19: TRESOR | F19: Laces | G19: Trim & Edging | H19: Mixed | I19: bundle | J19: 9 | K19: 410 | L19: 700 | M19: 700 | N19: =IF(OR(K19="",L19=""),"",(L19-K19)/L19) | O19: 0.05 | Q19: 1 | R19: 1 | S19: =IF(Q19="","",IF(Q19<=0,"OUT OF STOCK",IF(Q19<=R19,"REORDER","OK"))) | T19: =IF(B19="","",SUMIFS('Stock Log'!$D$2:$D$600,'Stock Log'!$B$2:$B$600,B19)) | U19: =IF(B19="","",IF(T19=Q19,"OK","CHECK")) | V19: 2026-07-09 | W19: Supplier A (rename me) | X19: https://tresorcouture.in/products/lace/HA6767.jpg | Y19: Studio | Z19: Yes | AA19: Active | AC19: Navy satin-twill ribbon with a looped antique-gold picot cord worked along one edge over a run of scalloped gold discs. A quiet, tailored trim for pipings, plackets and dupatta edges. 9-metre reel.
B20: HA6790 | C20: HA6790 | D20: Coral Vine Embroidered Organza Ribbon | E20: TRESOR | F20: Laces | G20: Trim & Edging | H20: Mixed | I20: bundle | J20: 9 | K20: 570 | L20: 985 | M20: 985 | N20: =IF(OR(K20="",L20=""),"",(L20-K20)/L20) | O20: 0.05 | Q20: 1 | R20: 1 | S20: =IF(Q20="","",IF(Q20<=0,"OUT OF STOCK",IF(Q20<=R20,"REORDER","OK"))) | T20: =IF(B20="","",SUMIFS('Stock Log'!$D$2:$D$600,'Stock Log'!$B$2:$B$600,B20)) | U20: =IF(B20="","",IF(T20=Q20,"OK","CHECK")) | V20: 2026-07-09 | W20: Supplier A (rename me) | X20: https://tresorcouture.in/products/lace/HA6790.jpg | Y20: Studio | Z20: Yes | AA20: Active | AC20: A sheer champagne organza ribbon embroidered with a trailing coral-and-peach floral vine, dotted with seed pearls, gold bugle beads and crystal accents. Delicate enough for necklines and baby hems. 9-metre reel.
B21: HA6979 | C21: HA6979 | D21: Black & Gold Jewelled Gimp Trim | E21: TRESOR | F21: Laces | G21: Trim & Edging | H21: Mixed | I21: bundle | J21: 9 | K21: 260 | L21: 450 | M21: 450 | N21: =IF(OR(K21="",L21=""),"",(L21-K21)/L21) | O21: 0.05 | Q21: 1 | R21: 1 | S21: =IF(Q21="","",IF(Q21<=0,"OUT OF STOCK",IF(Q21<=R21,"REORDER","OK"))) | T21: =IF(B21="","",SUMIFS('Stock Log'!$D$2:$D$600,'Stock Log'!$B$2:$B$600,B21)) | U21: =IF(B21="","",IF(T21=Q21,"OK","CHECK")) | V21: 2026-07-09 | W21: Supplier A (rename me) | X21: https://tresorcouture.in/products/lace/HA6979.jpg | Y21: Studio | Z21: Yes | AA21: Active | AC21: A black woven band where antique-gold cord loops frame amber and smoke crystals, alternating with small pearls — jewellery rendered as trim. Striking on velvet and festive black. 9-metre reel.
B22: HA6988 | C22: HA6988 | D22: Maroon Pearl Medallion Braid | E22: TRESOR | F22: Laces | G22: Trim & Edging | H22: Mixed | I22: bundle | J22: 9 | K22: 520 | L22: 890 | M22: 890 | N22: =IF(OR(K22="",L22=""),"",(L22-K22)/L22) | O22: 0.05 | Q22: 1 | R22: 1 | S22: =IF(Q22="","",IF(Q22<=0,"OUT OF STOCK",IF(Q22<=R22,"REORDER","OK"))) | T22: =IF(B22="","",SUMIFS('Stock Log'!$D$2:$D$600,'Stock Log'!$B$2:$B$600,B22)) | U22: =IF(B22="","",IF(T22=Q22,"OK","CHECK")) | V22: 2026-07-09 | W22: Supplier A (rename me) | X22: https://tresorcouture.in/products/lace/HA6988.jpg | Y22: Studio | Z22: Yes | AA22: Active | AC22: A maroon ground carrying gold crochet rings set with pearls down the centre, edged with a scalloped run of gold fans, each with its own pearl heart. Rich, temple-border colouring. 9-metre reel.
B23: HA7018 | C23: HA7018 | D23: Peach Daisy Chain Beaded Ribbon | E23: TRESOR | F23: Laces | G23: Trim & Edging | H23: Mixed | I23: bundle | J23: 9 | K23: 780 | L23: 1350 | M23: 1350 | N23: =IF(OR(K23="",L23=""),"",(L23-K23)/L23) | O23: 0.05 | Q23: 1 | R23: 1 | S23: =IF(Q23="","",IF(Q23<=0,"OUT OF STOCK",IF(Q23<=R23,"REORDER","OK"))) | T23: =IF(B23="","",SUMIFS('Stock Log'!$D$2:$D$600,'Stock Log'!$B$2:$B$600,B23)) | U23: =IF(B23="","",IF(T23=Q23,"OK","CHECK")) | V23: 2026-07-09 | W23: Supplier A (rename me) | X23: https://tresorcouture.in/products/lace/HA7018.jpg | Y23: Studio | Z23: Yes | AA23: Active | AC23: Sheer peach organza carrying a gold beaded vine: daisy medallions with olive thread centres, crystal teardrops, pearl sprays and bugle-bead leaves. Sweet without being sugary. 9-metre reel.
B24: MI263 | C24: MI263 | D24: Champagne Mirror-Work Trim | E24: TRESOR | F24: Laces | G24: Trim & Edging | H24: Mixed | I24: bundle | J24: 18 | K24: 260 | L24: 450 | M24: 450 | N24: =IF(OR(K24="",L24=""),"",(L24-K24)/L24) | O24: 0.05 | Q24: 1 | R24: 1 | S24: =IF(Q24="","",IF(Q24<=0,"OUT OF STOCK",IF(Q24<=R24,"REORDER","OK"))) | T24: =IF(B24="","",SUMIFS('Stock Log'!$D$2:$D$600,'Stock Log'!$B$2:$B$600,B24)) | U24: =IF(B24="","",IF(T24=Q24,"OK","CHECK")) | V24: 2026-07-09 | W24: Supplier A (rename me) | X24: https://tresorcouture.in/products/lace/MI263.jpg | Y24: Needs reshoot | Z24: Yes | AA24: Active | AC24: Rows of small round mirrors set on champagne-gold braid — classic shisha sparkle by the metre for ghagras, jackets and festive borders. Generous 18-metre reel. | AD24: Reshoot flagged — warehouse snapshot
B25: MO2029 | C25: MO2029 | D25: Cream Crystal Drop Fringe | E25: TRESOR | F25: Laces | G25: Trim & Edging | H25: Mixed | I25: bundle | J25: 9 | K25: 1160 | L25: 2000 | M25: 2000 | N25: =IF(OR(K25="",L25=""),"",(L25-K25)/L25) | O25: 0.05 | Q25: 1 | R25: 1 | S25: =IF(Q25="","",IF(Q25<=0,"OUT OF STOCK",IF(Q25<=R25,"REORDER","OK"))) | T25: =IF(B25="","",SUMIFS('Stock Log'!$D$2:$D$600,'Stock Log'!$B$2:$B$600,B25)) | U25: =IF(B25="","",IF(T25=Q25,"OK","CHECK")) | V25: 2026-07-09 | W25: Supplier A (rename me) | X25: https://tresorcouture.in/products/lace/MO2029.jpg | Y25: Studio | Z25: Yes | AA25: Active | AC25: A pale cream tulle header strung with pearls, dropping short tassels of faceted crystal and seed beads that swing as the wearer moves. For dupatta ends, blouse sleeves and hemlines that should move. 9-metre reel.
B26: MO3188 | C26: MO3188 | D26: Antique Gold Filigree Lattice Braid | E26: TRESOR | F26: Laces | G26: Trim & Edging | H26: Mixed | I26: bundle | J26: 18 | K26: 560 | L26: 960 | M26: 960 | N26: =IF(OR(K26="",L26=""),"",(L26-K26)/L26) | O26: 0.05 | Q26: 1 | R26: 1 | S26: =IF(Q26="","",IF(Q26<=0,"OUT OF STOCK",IF(Q26<=R26,"REORDER","OK"))) | T26: =IF(B26="","",SUMIFS('Stock Log'!$D$2:$D$600,'Stock Log'!$B$2:$B$600,B26)) | U26: =IF(B26="","",IF(T26=Q26,"OK","CHECK")) | V26: 2026-07-09 | W26: Supplier A (rename me) | X26: https://tresorcouture.in/products/lace/MO3188.jpg | Y26: Studio | Z26: Yes | AA26: Active | AC26: A crocheted antique-gold braid worked in a crossing lattice, with pearls seated along the weave and a beaded selvedge. Reads as heirloom metalwork. 18-metre reel.
B27: MO3392 | C27: MO3392 | D27: Pearl Lattice Organza Trim · Silver | E27: TRESOR | F27: Laces | G27: Trim & Edging | H27: Mixed | I27: bundle | J27: 7 | K27: 930 | L27: 1599 | M27: 1599 | N27: =IF(OR(K27="",L27=""),"",(L27-K27)/L27) | O27: 0.05 | Q27: 1 | R27: 1 | S27: =IF(Q27="","",IF(Q27<=0,"OUT OF STOCK",IF(Q27<=R27,"REORDER","OK"))) | T27: =IF(B27="","",SUMIFS('Stock Log'!$D$2:$D$600,'Stock Log'!$B$2:$B$600,B27)) | U27: =IF(B27="","",IF(T27=Q27,"OK","CHECK")) | V27: 2026-07-09 | W27: Supplier A (rename me) | X27: https://tresorcouture.in/products/lace/MO3392.jpg | Y27: Studio | Z27: Yes | AA27: Active | AC27: A sheer organza ribbon carrying a crisscross lattice of silver bugle beads with a full pearl string along one edge — bridal-white sparkle with real structure. 7-metre reel.
B28: MO3650 | C28: MO3650 | D28: Champagne Teardrop Crystal Fringe | E28: TRESOR | F28: Laces | G28: Trim & Edging | H28: Mixed | I28: bundle | J28: 9 | K28: 1390 | L28: 2400 | M28: 2400 | N28: =IF(OR(K28="",L28=""),"",(L28-K28)/L28) | O28: 0.05 | Q28: 1 | R28: 1 | S28: =IF(Q28="","",IF(Q28<=0,"OUT OF STOCK",IF(Q28<=R28,"REORDER","OK"))) | T28: =IF(B28="","",SUMIFS('Stock Log'!$D$2:$D$600,'Stock Log'!$B$2:$B$600,B28)) | U28: =IF(B28="","",IF(T28=Q28,"OK","CHECK")) | V28: 2026-07-09 | W28: Supplier A (rename me) | X28: https://tresorcouture.in/products/lace/MO3650.jpg | Y28: Studio | Z28: Yes | AA28: Active | AC28: Faceted champagne teardrop crystals hang from beaded stems along a sheer organza header — a fine chandelier fringe for dupatta ends and saree pallus. 9-metre reel.
B29: MO3857 | C29: MO3857 | D29: Sage Petal Drop Edging | E29: TRESOR | F29: Laces | G29: Trim & Edging | H29: Mixed | I29: bundle | J29: 9 | K29: 1330 | L29: 2300 | M29: 2300 | N29: =IF(OR(K29="",L29=""),"",(L29-K29)/L29) | O29: 0.05 | Q29: 1 | R29: 1 | S29: =IF(Q29="","",IF(Q29<=0,"OUT OF STOCK",IF(Q29<=R29,"REORDER","OK"))) | T29: =IF(B29="","",SUMIFS('Stock Log'!$D$2:$D$600,'Stock Log'!$B$2:$B$600,B29)) | U29: =IF(B29="","",IF(T29=Q29,"OK","CHECK")) | V29: 2026-07-09 | W29: Supplier A (rename me) | X29: https://tresorcouture.in/products/lace/MO3857.jpg | Y29: Studio | Z29: Yes | AA29: Active | AC29: A sage-green net edging with a short beaded fringe: clear crystal drops finished with tiny sequin petals in sage, mint and lilac. Subtle movement for pastel palettes. 9-metre reel.
B30: RI280 | C30: RI280 | D30: Taupe Picot Lattice Ribbon | E30: TRESOR | F30: Laces | G30: Trim & Edging | H30: Mixed | I30: bundle | J30: 9 | K30: 140 | L30: 250 | M30: 250 | N30: =IF(OR(K30="",L30=""),"",(L30-K30)/L30) | O30: 0.05 | Q30: 1 | R30: 1 | S30: =IF(Q30="","",IF(Q30<=0,"OUT OF STOCK",IF(Q30<=R30,"REORDER","OK"))) | T30: =IF(B30="","",SUMIFS('Stock Log'!$D$2:$D$600,'Stock Log'!$B$2:$B$600,B30)) | U30: =IF(B30="","",IF(T30=Q30,"OK","CHECK")) | V30: 2026-07-09 | W30: Supplier A (rename me) | X30: https://tresorcouture.in/products/lace/RI280.jpg | Y30: Studio | Z30: Yes | AA30: Active | AC30: A slim woven ribbon in taupe and old-gold with a pin-dot lattice centre and scalloped picot edges — an understated finishing trim for pipings and inner facings. 9-metre reel.
B31: RI4680 | C31: RI4680 | D31: Silver Braided Cord Trim | E31: TRESOR | F31: Laces | G31: Trim & Edging | H31: Mixed | I31: bundle | J31: 9 | K31: 170 | L31: 300 | M31: 300 | N31: =IF(OR(K31="",L31=""),"",(L31-K31)/L31) | O31: 0.05 | Q31: 1 | R31: 1 | S31: =IF(Q31="","",IF(Q31<=0,"OUT OF STOCK",IF(Q31<=R31,"REORDER","OK"))) | T31: =IF(B31="","",SUMIFS('Stock Log'!$D$2:$D$600,'Stock Log'!$B$2:$B$600,B31)) | U31: =IF(B31="","",IF(T31=Q31,"OK","CHECK")) | V31: 2026-07-09 | W31: Supplier A (rename me) | X31: https://tresorcouture.in/products/lace/RI4680.jpg | Y31: Studio | Z31: Yes | AA31: Active | AC31: A plaited silver cord braid with a fine chain edge — clean metallic structure for necklines, cuffs and sharp modern borders. 9-metre reel.
B32: RI5687 | C32: RI5687 | D32: Champagne Pearl Chain Trim | E32: TRESOR | F32: Laces | G32: Trim & Edging | H32: Mixed | I32: bundle | J32: 30 | K32: 160 | L32: 280 | M32: 280 | N32: =IF(OR(K32="",L32=""),"",(L32-K32)/L32) | O32: 0.05 | Q32: 1 | R32: 1 | S32: =IF(Q32="","",IF(Q32<=0,"OUT OF STOCK",IF(Q32<=R32,"REORDER","OK"))) | T32: =IF(B32="","",SUMIFS('Stock Log'!$D$2:$D$600,'Stock Log'!$B$2:$B$600,B32)) | U32: =IF(B32="","",IF(T32=Q32,"OK","CHECK")) | V32: 2026-07-09 | W32: Supplier A (rename me) | X32: https://tresorcouture.in/products/lace/RI5687.jpg | Y32: Needs reshoot | Z32: Yes | AA32: Active | AC32: A fine champagne-gold chain trim strung with seed pearls — a delicate running accent for edges and layering over wider borders. Supplied on a generous 30-metre roll. | AD32: Reshoot flagged — warehouse snapshot
B33: RI5839 | C33: RI5839 | D33: Gold Pyramid Stud & Wave Braid | E33: TRESOR | F33: Laces | G33: Trim & Edging | H33: Mixed | I33: bundle | J33: 18 | K33: 130 | L33: 230 | M33: 230 | N33: =IF(OR(K33="",L33=""),"",(L33-K33)/L33) | O33: 0.05 | Q33: 1 | R33: 1 | S33: =IF(Q33="","",IF(Q33<=0,"OUT OF STOCK",IF(Q33<=R33,"REORDER","OK"))) | T33: =IF(B33="","",SUMIFS('Stock Log'!$D$2:$D$600,'Stock Log'!$B$2:$B$600,B33)) | U33: =IF(B33="","",IF(T33=Q33,"OK","CHECK")) | V33: 2026-07-09 | W33: Supplier A (rename me) | X33: https://tresorcouture.in/products/lace/RI5839.jpg | Y33: Studio | Z33: Yes | AA33: Active | AC33: Two gold trims in one band: a row of faceted pyramid studs beside a scalloped wave braid worked in metallic thread. Architectural shine for waistbands and borders. 18-metre reel.
B34: ST3382 | C34: ST3382 | D34: Citrine Crystal Encrusted Band | E34: TRESOR | F34: Laces | G34: Trim & Edging | H34: Mixed | I34: bundle | J34: 9 | K34: 930 | L34: 1599 | M34: 1599 | N34: =IF(OR(K34="",L34=""),"",(L34-K34)/L34) | O34: 0.05 | Q34: 1 | R34: 1 | S34: =IF(Q34="","",IF(Q34<=0,"OUT OF STOCK",IF(Q34<=R34,"REORDER","OK"))) | T34: =IF(B34="","",SUMIFS('Stock Log'!$D$2:$D$600,'Stock Log'!$B$2:$B$600,B34)) | U34: =IF(B34="","",IF(T34=Q34,"OK","CHECK")) | V34: 2026-07-09 | W34: Supplier A (rename me) | X34: https://tresorcouture.in/products/lace/ST3382.jpg | Y34: Studio | Z34: Yes | AA34: Active | AC34: Five dense rows of citrine-gold rhinestones claw-set in metallic thread on silver net — a solid runway of stones for belts, borders and blouse straps. 9-metre reel.
B35: ST987 | C35: ST987 | D35: Gold Infinity Loop Pearl Braid | E35: TRESOR | F35: Laces | G35: Trim & Edging | H35: Mixed | I35: bundle | J35: 18 | K35: 160 | L35: 280 | M35: 280 | N35: =IF(OR(K35="",L35=""),"",(L35-K35)/L35) | O35: 0.05 | Q35: 1 | R35: 1 | S35: =IF(Q35="","",IF(Q35<=0,"OUT OF STOCK",IF(Q35<=R35,"REORDER","OK"))) | T35: =IF(B35="","",SUMIFS('Stock Log'!$D$2:$D$600,'Stock Log'!$B$2:$B$600,B35)) | U35: =IF(B35="","",IF(T35=Q35,"OK","CHECK")) | V35: 2026-07-09 | W35: Supplier A (rename me) | X35: https://tresorcouture.in/products/lace/ST987.jpg | Y35: Studio | Z35: Yes | AA35: Active | AC35: Antique-gold cord worked in interlocking infinity loops, alternating seed pearls and tiny rhinestones down the line — fine jewellery scaled to a border. 18-metre reel.
B36: lc-ih-ivory | D36: Ivory Heritage Lehenga · Ivory | E36: TRESOR COUTURE | F36: Lehenga Cholis | G36: Ivory Heritage | H36: Net | I36: unit | K36: 22320 | L36: 35999 | M36: 35999 | N36: =IF(OR(K36="",L36=""),"",(L36-K36)/L36) | O36: 0.05 | Q36: 5 | R36: 2 | S36: =IF(Q36="","",IF(Q36<=0,"OUT OF STOCK",IF(Q36<=R36,"REORDER","OK"))) | T36: =IF(B36="","",SUMIFS('Stock Log'!$D$2:$D$600,'Stock Log'!$B$2:$B$600,B36)) | U36: =IF(B36="","",IF(T36=Q36,"OK","CHECK")) | V36: 2026-07-31 | W36: Atelier — own production | X36: https://tresorcouture.in/products/lehenga/pearl-ivory.jpg | Y36: Studio | Z36: Yes | AA36: Active | AB36: New In | AC36: White-on-white throughout: a geometric jaal across the skirt panels resolving into a dense floral border, worked in matte thread and pearl on ivory. Sleeveless boat-neck choli, sheer dupatta scattered with pearl motifs. Made for a daytime or church ceremony.
B37: lc-ps-antique-gold | D37: Pearl Strand Lehenga · Antique Gold | E37: TRESOR COUTURE | F37: Lehenga Cholis | G37: Pearl Strand | H37: Net | I37: unit | K37: 22320 | L37: 35999 | M37: 35999 | N37: =IF(OR(K37="",L37=""),"",(L37-K37)/L37) | O37: 0.05 | Q37: 5 | R37: 2 | S37: =IF(Q37="","",IF(Q37<=0,"OUT OF STOCK",IF(Q37<=R37,"REORDER","OK"))) | T37: =IF(B37="","",SUMIFS('Stock Log'!$D$2:$D$600,'Stock Log'!$B$2:$B$600,B37)) | U37: =IF(B37="","",IF(T37=Q37,"OK","CHECK")) | V37: 2026-07-31 | W37: Atelier — own production | X37: https://tresorcouture.in/products/lehenga/pearl-antique-gold.jpg | Y37: Studio | Z37: Yes | AA37: Active | AB37: New In | AC37: Vertical strands of pearl and bead fall the length of the antique-gold skirt, opening into a hand-worked floral field at the hem. A scoop-neck choli edged in pearl drops, with a matching net dupatta bordered in the same strand work.
B38: lc-tw-blush | D38: Threadwork Lehenga · Blush | E38: TRESOR COUTURE | F38: Lehenga Cholis | G38: Threadwork | H38: Net | I38: unit | K38: 22320 | L38: 35999 | M38: 35999 | N38: =IF(OR(K38="",L38=""),"",(L38-K38)/L38) | O38: 0.05 | Q38: 5 | R38: 2 | S38: =IF(Q38="","",IF(Q38<=0,"OUT OF STOCK",IF(Q38<=R38,"REORDER","OK"))) | T38: =IF(B38="","",SUMIFS('Stock Log'!$D$2:$D$600,'Stock Log'!$B$2:$B$600,B38)) | U38: =IF(B38="","",IF(T38=Q38,"OK","CHECK")) | V38: 2026-07-31 | W38: Atelier — own production | X38: https://tresorcouture.in/products/lehenga/thread-blush.jpg | Y38: Studio | Z38: Yes | AA38: Active | AB38: New In | AC38: Blush-on-blush: the threadwork colourway for haldi mornings and daytime mehendi, soft enough for sunlight and detailed enough for the close-up. Dense tonal embroidery across the flare, sweetheart neckline, sheer dupatta, scalloped edge in the same thread.
B39: lc-tw-crimson | D39: Threadwork Lehenga · Crimson | E39: TRESOR COUTURE | F39: Lehenga Cholis | G39: Threadwork | H39: Net | I39: unit | K39: 22320 | L39: 35999 | M39: 35999 | N39: =IF(OR(K39="",L39=""),"",(L39-K39)/L39) | O39: 0.05 | Q39: 5 | R39: 2 | S39: =IF(Q39="","",IF(Q39<=0,"OUT OF STOCK",IF(Q39<=R39,"REORDER","OK"))) | T39: =IF(B39="","",SUMIFS('Stock Log'!$D$2:$D$600,'Stock Log'!$B$2:$B$600,B39)) | U39: =IF(B39="","",IF(T39=Q39,"OK","CHECK")) | V39: 2026-07-31 | W39: Atelier — own production | X39: https://tresorcouture.in/products/lehenga/thread-crimson.jpg | Y39: Studio | Z39: Yes | AA39: Active | AB39: New In | AC39: Crimson is this silhouette at full volume — traditional bridal red, but rendered in tone-on-tone thread rather than metal, so it moves like fabric instead of armour. Full embroidered flare, sweetheart choli on wide straps, buti dupatta, scalloped hem.
B40: lc-tw-ivory | D40: Threadwork Lehenga · Ivory | E40: TRESOR COUTURE | F40: Lehenga Cholis | G40: Threadwork | H40: Net | I40: unit | K40: 22320 | L40: 35999 | M40: 35999 | N40: =IF(OR(K40="",L40=""),"",(L40-K40)/L40) | O40: 0.05 | Q40: 5 | R40: 2 | S40: =IF(Q40="","",IF(Q40<=0,"OUT OF STOCK",IF(Q40<=R40,"REORDER","OK"))) | T40: =IF(B40="","",SUMIFS('Stock Log'!$D$2:$D$600,'Stock Log'!$B$2:$B$600,B40)) | U40: =IF(B40="","",IF(T40=Q40,"OK","CHECK")) | V40: 2026-07-31 | W40: Atelier — own production | X40: https://tresorcouture.in/products/lehenga/thread-ivory.jpg | Y40: Studio | Z40: Yes | AA40: Active | AB40: New In | AC40: The ivory colourway is the quiet bridal option — white-on-white threadwork with a soft sheen, closer to couture lingerie than costume. All-over tonal embroidery, sweetheart choli, sheer dupatta with scattered butis and a scallop-finished hem.
...

Sheet Stock Log
A1: Date | B1: Product ID | C1: What Happened | D1: Qty (+ in / − out) | E1: Stock After | F1: Reference (PO / Order no.) | G1: Notes
A2: 2026-07-09 | B2: 6343 | C2: Opening stock | D2: 1 | E2: =IF($B2="","",SUMIFS($D$2:$D2,$B$2:$B2,$B2)) | F2: IMPORT-0709 | G2: Stock on hand when this sheet was started
A3: 2026-07-09 | B3: 6988 | C3: Opening stock | D3: 1 | E3: =IF($B3="","",SUMIFS($D$2:$D3,$B$2:$B3,$B3)) | F3: IMPORT-0709 | G3: Stock on hand when this sheet was started
A4: 2026-07-09 | B4: HA3858 | C4: Opening stock | D4: 2 | E4: =IF($B4="","",SUMIFS($D$2:$D4,$B$2:$B4,$B4)) | F4: IMPORT-0709 | G4: Stock on hand when this sheet was started
A5: 2026-07-09 | B5: HA4536 | C5: Opening stock | D5: 1 | E5: =IF($B5="","",SUMIFS($D$2:$D5,$B$2:$B5,$B5)) | F5: IMPORT-0709 | G5: Stock on hand when this sheet was started
A6: 2026-07-09 | B6: HA6293 | C6: Opening stock | D6: 1 | E6: =IF($B6="","",SUMIFS($D$2:$D6,$B$2:$B6,$B6)) | F6: IMPORT-0709 | G6: Stock on hand when this sheet was started
A7: 2026-07-09 | B7: HA6320 | C7: Opening stock | D7: 1 | E7: =IF($B7="","",SUMIFS($D$2:$D7,$B$2:$B7,$B7)) | F7: IMPORT-0709 | G7: Stock on hand when this sheet was started
A8: 2026-07-09 | B8: HA6378 | C8: Opening stock | D8: 1 | E8: =IF($B8="","",SUMIFS($D$2:$D8,$B$2:$B8,$B8)) | F8: IMPORT-0709 | G8: Stock on hand when this sheet was started
A9: 2026-07-09 | B9: HA6387 | C9: Opening stock | D9: 1 | E9: =IF($B9="","",SUMIFS($D$2:$D9,$B$2:$B9,$B9)) | F9: IMPORT-0709 | G9: Stock on hand when this sheet was started
A10: 2026-07-09 | B10: HA6674 | C10: Opening stock | D10: 1 | E10: =IF($B10="","",SUMIFS($D$2:$D10,$B$2:$B10,$B10)) | F10: IMPORT-0709 | G10: Stock on hand when this sheet was started
A11: 2026-07-09 | B11: HA6758 | C11: Opening stock | D11: 1 | E11: =IF($B11="","",SUMIFS($D$2:$D11,$B$2:$B11,$B11)) | F11: IMPORT-0709 | G11: Stock on hand when this sheet was started
A12: 2026-07-09 | B12: HA6767 | C12: Opening stock | D12: 1 | E12: =IF($B12="","",SUMIFS($D$2:$D12,$B$2:$B12,$B12)) | F12: IMPORT-0709 | G12: Stock on hand when this sheet was started
A13: 2026-07-09 | B13: HA6790 | C13: Opening stock | D13: 1 | E13: =IF($B13="","",SUMIFS($D$2:$D13,$B$2:$B13,$B13)) | F13: IMPORT-0709 | G13: Stock on hand when this sheet was started
... A60: 2026-08-13 | B60: MI263 | C60: Sold - Online | D60: -1 | E60: =IF($B60="","",SUMIFS($D$2:$D60,$B$2:$B60,$B60)) | F60: ORD-8V9A | G60: COD order
E61: =IF($B61="","",SUMIFS($D$2:$D61,$B$2:$B61,$B61))
E62: =IF($B62="","",SUMIFS($D$2:$D62,$B$2:$B62,$B62))
E63: =IF($B63="","",SUMIFS($D$2:$D63,$B$2:$B63,$B63))
E64: =IF($B64="","",SUMIFS($D$2:$D64,$B$2:$B64,$B64))
E65: =IF($B65="","",SUMIFS($D$2:$D65,$B$2:$B65,$B65))
E66: =IF($B66="","",SUMIFS($D$2:$D66,$B$2:$B66,$B66))
E67: =IF($B67="","",SUMIFS($D$2:$D67,$B$2:$B67,$B67))
E68: =IF($B68="","",SUMIFS($D$2:$D68,$B$2:$B68,$B68))
E69: =IF($B69="","",SUMIFS($D$2:$D69,$B$2:$B69,$B69))
E70: =IF($B70="","",SUMIFS($D$2:$D70,$B$2:$B70,$B70))
E71: =IF($B71="","",SUMIFS($D$2:$D71,$B$2:$B71,$B71))
E72: =IF($B72="","",SUMIFS($D$2:$D72,$B$2:$B72,$B72))
... E600: =IF($B600="","",SUMIFS($D$2:$D600,$B$2:$B600,$B600))

Sheet Orders & Returns
A1: Order Date | B1: Order No. | C1: Channel | D1: Customer | E1: City / Country | F1: Product ID | G1: Qty | H1: Order Value (₹) | I1: Payment | J1: Fulfilment | K1: Return Status | L1: Refund (₹) | M1: Refund Date | N1: Notes
A2: 2026-08-02 | B2: ORD-8H2K | C2: Website - COD | D2: Customer 1 | E2: Hyderabad | F2: 6343 | G2: 1 | H2: 7000 | I2: COD - collected | J2: Delivered
A3: 2026-08-04 | B3: ORD-8J7Q | C3: Website - COD | D3: Customer 2 | E3: Secunderabad | F3: 6988 | G3: 1 | H3: 999 | I3: COD - collected | J3: Delivered
A4: 2026-08-05 | B4: ORD-8L4R | C4: Website - Prepaid | D4: Customer 3 | E4: Hyderabad | F4: lc-zf-rose | G4: 1 | H4: 35999 | I4: Refunded | J4: Delivered | K4: Refunded | L4: 35999 | M4: 2026-08-14 | N4: Size exchange requested; piece restocked after inspection — see Stock Log RET-8L4R
A5: 2026-08-07 | B5: ORD-8N1D | C5: Website - COD | D5: Customer 4 | E5: Warangal | F5: HA4536 | G5: 1 | H5: 3800 | I5: COD - collected | J5: Delivered
A6: 2026-08-09 | B6: ORD-8Q5S | C6: In Store | D6: Walk-in | E6: Hyderabad | F6: HA6320 | G6: 1 | H6: 4800 | I6: Prepaid - paid | J6: Delivered | N6: Studio walk-in
A7: 2026-08-11 | B7: ORD-8T3M | C7: Website - COD | D7: Customer 5 | E7: Vijayawada | F7: HA3858 | G7: 1 | H7: 1299 | I7: COD - to collect | J7: Shipped
A8: 2026-08-13 | B8: ORD-8V9A | C8: WhatsApp / DM | D8: Customer 6 | E8: Hyderabad | F8: MI263 | G8: 1 | H8: 450 | I8: Prepaid - paid | J8: Delivered | N8: Instagram DM enquiry

Sheet Action Tracker
A1: # | B1: Task | C1: Area | D1: Status | E1: Owner | F1: Done Date | G1: Notes
A2: 1 | B2: Rotate the Firebase service-account key (Firebase Console → Project settings → Service accounts → generate new, delete old) | C2: Security | D2: Pending | E2: You | G2: Current key was shared in chat — treat as exposed
A3: 2 | B3: Regenerate the live Razorpay Key Secret; update RAZORPAY_KEY_SECRET in Vercel | C3: Security | D3: Pending | E3: You | G3: Old secret appeared in a screenshot
A4: 3 | B4: Paste VITE_GSTIN (from the GST certificate) into Vercel and redeploy | C4: Compliance | D4: Pending | E4: You | G4: Until then invoices/footer omit the GSTIN by design
A5: 4 | B5: Update VITE_BUSINESS_ADDRESS in Vercel to the full registered address (Gachibowli · 500046) | C5: Compliance | D5: Pending | E5: You | G5: Must match the GST certificate on invoices
A6: 5 | B6: Add CRON_SECRET + GOOGLE_REVIEW_URL in Vercel to switch on the review-request emails | C6: Marketing | D6: Pending | E6: You | G6: Cron is deployed and waiting on these two values
A7: 6 | B7: Create the free Microsoft Clarity project; paste VITE_CLARITY_PROJECT_ID into Vercel; redeploy | C7: Marketing | D7: Pending | E7: You | G7: Heatmaps + session recordings, consent-gated
A8: 7 | B8: Connect Google Search Console (Domain property, DNS TXT) and submit sitemap.xml | C8: SEO | D8: Pending | E8: You | G8: 62 real URLs are live and waiting to be indexed
A9: 8 | B9: Request indexing for home, Lehenga Cholis category, and 2–3 product pages (URL Inspection) | C9: SEO | D9: Pending | E9: You | G9: After Search Console verifies
A10: 9 | B10: Google Business Profile: rewrite description (boutique, not fabric house), add secondary categories, In-store shopping, full address + PIN | C10: Marketing | D10: Pending | E10: You | G10: Draft description was provided in chat
A11: 10 | B11: Google Business Profile: upload logo, cover photo, 15–25 real photos; set hours; add Products | C11: Marketing | D11: Pending | E11: You | G11: Profile strength currently 64%
A12: 11 | B12: Collect the first 15–25 Google reviews (ask at handover + review-request email) | C12: Marketing | D12: Pending | E12: You | G12: Zero reviews today — the #1 local ranking factor
A13: 12 | B13: CA: confirm GST rates (5% vs 18% over ₹2,500/piece) and HSN codes per category | C13: Finance | D13: Pending | E13: CA | G13: Then per-product rates get wired into checkout + invoices
... A19: 18 | B19: If exporting: IEC registration + LUT filing (zero-rated exports without paying IGST) | C19: Finance | D19: Pending | E19: CA | G19: Only when international orders start

Sheet How To Use
B2: TRESOR COUTURE — MASTER CATALOGUE (read this page first)
B4: WHAT EACH SHEET IS FOR
B5: Catalogue = your products. One row per item you sell. This is where prices, stock and photos live.
B6: Stock Log = a diary of stock. Every time stock moves — in or out — you add ONE line at the bottom. You never edit old lines.
B7: Orders & Returns = your orders. One row per customer order. Refunds and return progress are tracked HERE, because a refund is about money, not stock.
B8: Action Tracker = your to-do list. Filter the Status column to "Pending" to see everything left to do; set it to "Done" with a date when finished.
B9: Lists = the options inside every dropdown. Add a new supplier or category here once and every dropdown learns it.
B11: UPLOADING THIS SHEET TO THE WEBSITE
B12: This workbook is not just a record — the Catalogue sheet can be imported straight into the website. Product ID is the key: a new ID creates a product, an existing ID updates it. Nothing is ever deleted by an import.
B13: Every product you import gets its own barcode (TC00001, TC00002, …) automatically, and you can print the labels from Admin → Inventory → Print labels. A product keeps the same barcode forever, so re-importing is safe.
B14: Description = what the customer reads on the product page and what Google indexes. Two or three real sentences per product. Leave it blank and the import keeps whatever the site already has — a blank cell never wipes existing copy.
B15: Listing Status decides what shoppers see. "Active" = on the website. "Draft" = in the system (stock, barcode, counter billing) but NOT on the website. "Retired" = taken down. No photo yet? Leave Image URL blank — the import files it as Draft on its own, so you can register the whole store now and publish each piece the day it is photographed.
... B43: Buying prices are ILLUSTRATIVE (the website database stores no cost prices yet) — replace with real PO costs. GST is left at 5% with HSN blank pending your CA; garments above ₹2,500/piece likely attract 18%. The orders and stock movements are format examples using your real products and current stock levels. Generated from the live site database on 2026-08-16.

Sheet Lists
B1: Material | C1: Unit Type | D1: GST Rate | E1: Photo Quality | F1: Live on Site | G1: Listing Status | H1: Sticker | I1: Movement | J1: Supplier | K1: Channel | L1: Payment | M1: Fulfilment | N1: Return Status | O1: Task Area | P1: Task Status
A2: Fabrics | B2: Silk | C2: unit | D2: 0 | E2: Studio | F2: Yes | G2: Active | H2: New In | I2: Opening stock | J2: Supplier A (rename me) | K2: Website - COD | L2: COD - to collect | M2: Placed | N2: Requested | O2: Marketing | P2: Pending
A3: Dyeable Fabrics | B3: Silk blend | C3: per meter | D3: 0.05 | E3: Acceptable | F3: No | G3: Draft | H3: Bestseller | I3: Received (new stock) | J3: Supplier B (rename me) | K3: Website - Prepaid | L3: COD - collected | M3: Packed | N3: Approved | O3: SEO | P3: In progress
A4: Laces | B4: Cotton | C4: bundle | D4: 0.12 | E4: Needs reshoot | G4: Retired | H4: Trending | I4: Sold - Online | J4: Atelier — own production | K4: In Store | L4: Prepaid - paid | M4: Shipped | N4: Pickup arranged | O4: Compliance | P4: Blocked
A5: Sarees | B5: Wool | D5: 0.18 | H5: Limited | I5: Sold - In Store | K5: WhatsApp / DM | L5: Refunded | M5: Delivered | N5: Received back | O5: Finance | P5: Done
A6: One Minute Saree | B6: Linen | I6: Sold - Export | K6: Export | L6: Partly refunded | M6: Cancelled | N6: Refunded | O6: Catalogue
A7: Half Saree | B7: Satin | I7: Returned (back to stock) | N7: Replaced | O7: Security
A8: Lehenga Cholis | B8: Net | I8: Damaged / Write-off | N8: Rejected | O8: Operations
A9: Langha Jacket | B9: Georgette | I9: Sample / Gift
A10: Anarkalis | B10: Organza | I10: Count correction
A11: Gown | B11: Mixed
A12: Three Piece Set
A13: Ethnic Wear
A14: Masakhali
A15: Western Wear
A16: Studios Prêt
